I'm sorry, but an uncaught exception occurred.

While running game code:
  File "game/end_scripts.rpy", line 33, in script
    P "Well. Go play catch."
Exception: Sayer 'P' is not defined.

-- Full Traceback ------------------------------------------------------------

Full traceback:
  File "game/end_scripts.rpy", line 33, in script
    P "Well. Go play catch."
  File "C:\Users\itms2\NotOneDrive\FeedingTheVelociraptors\renpy\ast.py", line 676, in execute
    who = eval_who(self.who, self.who_fast)
  File "C:\Users\itms2\NotOneDrive\FeedingTheVelociraptors\renpy\ast.py", line 574, in eval_who
    raise Exception("Sayer '%s' is not defined." % who.encode("utf-8"))
Exception: Sayer 'P' is not defined.

Windows-8-6.2.9200
Ren'Py 7.3.2.320
Jam and the Mystery of the Mysteriously Spooky Mansion 1.2
Wed Jan 19 16:27:40 2022
